Workbook

Sheet PROP DAILY PNL
A1: Date | B1: PNL | C1: Percentage Return | D1: MR PNL | E1: Absolute PNL on NAV | F1: NAV VALUE | G1: MAX DD | H1: DD | I1: 0 Dte PNL | J1: NEW NIFTY RANGE BO | K1: NIFTY RSI | L1: NON dte setup | M1: NIFTY DIREC | N1: MIDCAP ORB | O1: MIDCAP RSI | P1: BANKS RSI | Q1: Non direc EMI | R1: VWAP/EMA (WEF 1 DEC) | S1: EMA QTY | T1: pts | U1: cumm pts | V1: ND SYSTEM | W1: Non dte Qty | X1: Pts | Y1: Cumm pts | Z1: Direct Day wise profit/loss | AA1: Cumm Direct PNL | AB1: QTY NON Directional | AC1: NON direc pts | AD1: Cumm Non dte pts | AE1: Nifty Direc Qty | AF1: Pts | AG1: Cumm Pts | AH1: ND system QTY | AI1: Pts | AJ1: Cumm Pts | AK1: NIFTY ORB QTy | AL1: Pts | AM1: Cumm Pts | AN1: NIFTY Pts | AO1: NIFTY RSI cumm pts | AP1: MIDCP ORB QTY | AQ1: Pts | AR1: Cumm Pts | AS1: MIDCAP RSI QTY | AT1: MIDCAP RSI PTS | AU1: MIDCAP CUm pts | AV1: BANKS RSI QTY | AW1: BANKS Pts RSI | AX1: BANKS Cumm pts | AY1: MR qty | AZ1: MR | BA1: MR CUMM pts | BE1: Learnings
A2: 45446 | B2: 82622.25 | C2: =B2/'Clients Balance'!B2 -> 0.027032106 | E2: =C2*100 -> 2.7032106 | F2: =100*(1+C2) -> 102.70321 | G2: =MAX($F$2:F2) -> 102.70321 | H2: =(F2-G2)/F2 -> 0
A3: 45447 | B3: 155760 | C3: =B3/'Clients Balance'!B3 -> 0.049619774 | E3: =C3*F2 -> 5.0961101 | F3: =F2*(1+C3) -> 107.79932 | G3: =MAX($F$2:F3) -> 107.79932 | H3: =(F3-G3)/F3 -> 0
A4: 45448 | B4: -13672.5 | C4: =B4/'Clients Balance'!B4 -> -0.0041496816 | E4: =C4*F3 -> -0.44733286 | F4: =F3*(1+C4) -> 107.35199 | G4: =MAX($F$2:F4) -> 107.79932 | H4: =(F4-G4)/F4 -> -0.0041669732
A5: 45449 | B5: =11487-5580 -> 5907 | C5: =B5/'Clients Balance'!B5 -> 0.0018002787 | E5: =C5*F4 -> 0.1932635 | F5: =F4*(1+C5) -> 107.54525 | G5: =MAX($F$2:F5) -> 107.79932 | H5: =(F5-G5)/F5 -> -0.0023624414
A6: 45450 | B6: 32298 | C6: =B6/'Clients Balance'!B6 -> 0.009825785 | E6: =C6*F5 -> 1.0567165 | F6: =F5*(1+C6) -> 108.60197 | G6: =MAX($F$2:F6) -> 108.60197 | H6: =(F6-G6)/F6 -> 0
A7: 45453 | B7: 32068.5 | C7: =B7/'Clients Balance'!B7 -> 0.0096610386 | E7: =C7*F6 -> 1.0492078 | F7: =F6*(1+C7) -> 109.65118 | G7: =MAX($F$2:F7) -> 109.65118 | H7: =(F7-G7)/F7 -> 0
A8: 45454 | B8: 537 | C8: =B8/'Clients Balance'!B8 -> 0.00016023001 | E8: =C8*F7 -> 0.017569409 | F8: =F7*(1+C8) -> 109.66875 | G8: =MAX($F$2:F8) -> 109.66875 | H8: =(F8-G8)/F8 -> 0
A9: 45455 | B9: -8304 | C9: =B9/'Clients Balance'!B9 -> -0.0024773498 | E9: =C9*F8 -> -0.27168784 | F9: =F8*(1+C9) -> 109.39706 | G9: =MAX($F$2:F9) -> 109.66875 | H9: =(F9-G9)/F9 -> -0.0024835023
A10: 45456 | B10: 9743.25 | C10: =B10/'Clients Balance'!B10 -> 0.0029139431 | E10: =C10*F9 -> 0.3187768 | F10: =F9*(1+C10) -> 109.71583 | G10: =MAX($F$2:F10) -> 109.71583 | H10: =(F10-G10)/F10 -> 0
A11: 45457 | B11: 485.5 | C11: =B11/'Clients Balance'!B11 -> 0.00014477807 | E11: =C11*F10 -> 0.015884447 | F11: =F10*(1+C11) -> 109.73172 | G11: =MAX($F$2:F11) -> 109.73172 | H11: =(F11-G11)/F11 -> 0
A12: 45461 | B12: 6382.25 | C12: =B12/'Clients Balance'!B12 -> 0.0019029374 | E12: =C12*F11 -> 0.20881259 | F12: =F11*(1+C12) -> 109.94053 | G12: =MAX($F$2:F12) -> 109.94053 | H12: =(F12-G12)/F12 -> 0
A13: 45462 | B13: -57802.75 | C13: =B13/'Clients Balance'!B13 -> -0.017201786 | E13: =C13*F12 -> -1.8911735 | F13: =F12*(1+C13) -> 108.04936 | G13: =MAX($F$2:F13) -> 109.94053 | H13: =(F13-G13)/F13 -> -0.017502866
A14: 45463 | B14: 4544 | C14: =B14/'Clients Balance'!B14 -> 0.0013759384 | E14: =C14*F13 -> 0.14866926 | F14: =F13*(1+C14) -> 108.19803 | G14: =MAX($F$2:F14) -> 109.94053 | H14: =(F14-G14)/F14 -> -0.016104769
A15: 45464 | B15: -64673.25 | C15: =B15/'Clients Balance'!B15 -> -0.019556368 | E15: =C15*F14 -> -2.1159605 | F15: =F14*(1+C15) -> 106.08207 | G15: =MAX($F$2:F15) -> 109.94053 | H15: =(F15-G15)/F15 -> -0.03637245
A16: 45467 | B16: 30066 | C16: =B16/'Clients Balance'!B16 -> 0.0092729207 | E16: =C16*F15 -> 0.98369059 | F16: =F15*(1+C16) -> 107.06576 | G16: =MAX($F$2:F16) -> 109.94053 | H16: =(F16-G16)/F16 -> -0.026850546 | I16: =B16-K16 -> 30066
A17: 45468 | B17: 60457 | C17: =B17/'Clients Balance'!B17 -> 0.018474763 | E17: =C17*F16 -> 1.9780144 | F17: =F16*(1+C17) -> 109.04377 | G17: =MAX($F$2:F17) -> 109.94053 | H17: =(F17-G17)/F17 -> -0.0082238502 | I17: =B17-K17 -> 60457
A18: 45469 | B18: 46637.5 | C18: =B18/'Clients Balance'!B18 -> 0.013993207 | E18: =C18*F17 -> 1.5258721 | F18: =F17*(1+C18) -> 110.56964 | G18: =MAX($F$2:F18) -> 110.56964 | H18: =(F18-G18)/F18 -> 0 | I18: =B18-K18 -> 40845 | K18: 5792.5 | AK18: 850 | AN18: =K18/AK18 -> 6.8147059 | AO18: =AN18 -> 6.8147059
A19: 45470 | B19: -142558.75 | C19: =B19/'Clients Balance'!B19 -> -0.042183327 | E19: =C19*F18 -> -4.6641955 | F19: =F18*(1+C19) -> 105.90545 | G19: =MAX($F$2:F19) -> 110.56964 | H19: =(F19-G19)/F19 -> -0.044041129 | I19: =B19-K19 -> -46912.5 | K19: =-23841.25-17723.75-47910-26702.5+20531.25 -> -95646.25 | AK19: 850 | AN19: =K19/AK19 -> -112.525 | AO19: =AO18+AN19 -> -105.71029
A20: 45471 | B20: -57876.25 | C20: =B20/'Clients Balance'!B20 -> -0.017879894 | E20: =C20*F19 -> -1.8935782 | F20: =F19*(1+C20) -> 104.01187 | G20: =MAX($F$2:F20) -> 110.56964 | H20: =(F20-G20)/F20 -> -0.06304832 | I20: =B20-K20 -> -17122.5 | K20: =-41796.25-12518.75+13561.25 -> -40753.75 | AK20: 850 | AN20: =K20/AK20 -> -47.945588 | AO20: =AO19+AN20 -> -153.65588
A21: 45474 | B21: -11219 | C21: =B21/'Clients Balance'!B21 -> -0.0035290199 | E21: =C21*F20 -> -0.36705996 | F21: =F20*(1+C21) -> 103.64481 | G21: =MAX($F$2:F21) -> 110.56964 | H21: =(F21-G21)/F21 -> -0.066813125 | I21: =B21-K21 -> -3569 | K21: -7650 | AK21: 850 | AN21: =K21/AK21 -> -9 | AO21: =AO20+AN21 -> -162.65588
A22: 45475 | B22: -24815.5 | C22: =B22/'Clients Balance'!B22 -> -0.0080709209 | E22: =C22*F21 -> -0.83650906 | F22: =F21*(1+C22) -> 102.8083 | G22: =MAX($F$2:F22) -> 110.56964 | H22: =(F22-G22)/F22 -> -0.075493347 | I22: =B22-K22 -> -5048 | K22: -19767.5 | AK22: 850 | AN22: =K22/AK22 -> -23.255882 | AO22: =AO21+AN22 -> -185.91176
A23: 45476 | B23: 112503.75 | C23: =B23/'Clients Balance'!B23 -> 0.036717719 | E23: =C23*F22 -> 3.7748863 | F23: =F22*(1+C23) -> 106.58319 | G23: =MAX($F$2:F23) -> 110.56964 | H23: =(F23-G23)/F23 -> -0.0374023 | I23: =B23-K23 -> 113913.75 | K23: =4256.25-5666.25 -> -1410 | AK23: 850 | AN23: =K23/AK23 -> -1.6588235 | AO23: =AO22+AN23 -> -187.57059
A24: 45477 | B24: 39878.75 | C24: =B24/'Clients Balance'!B24 -> 0.013120885 | E24: =C24*F23 -> 1.3984657 | F24: =F23*(1+C24) -> 107.98165 | G24: =MAX($F$2:F24) -> 110.56964 | H24: =(F24-G24)/F24 -> -0.023966948 | I24: =B24-K24 -> 77998.75 | K24: =-720-37400 -> -38120 | AK24: 850 | AN24: =K24/AK24 -> -44.847059 | AO24: =AO23+AN24 -> -232.41765
A25: 45478 | B25: -25744.5 | C25: =B25/'Clients Balance'!B25 -> -0.0081680919 | E25: =C25*F24 -> -0.88200407 | F25: =F24*(1+C25) -> 107.09965 | G25: =MAX($F$2:F25) -> 110.56964 | H25: =(F25-G25)/F25 -> -0.032399684 | I25: =B25-K25 -> -582.5 | K25: -25162 | AK25: 975 | AN25: -40 | AO25: =AO24+AN25 -> -272.41765
A26: 45481 | B26: -44632.5 | C26: =B26/'Clients Balance'!B26 -> -0.013983855 | E26: =C26*F25 -> -1.497666 | F26: =F25*(1+C26) -> 105.60198 | G26: =MAX($F$2:F26) -> 110.56964 | H26: =(F26-G26)/F26 -> -0.047041358 | I26: =B26-K26 -> -44632.5 | K26: 0 | AK26: 975 | AN26: =K26/AK26 -> 0 | AO26: =AO25+AN26 -> -272.41765
A27: 45482 | B27: -12644.75 | C27: =B27/'Clients Balance'!B27 -> -0.0039939552 | E27: =C27*F26 -> -0.42176959 | F27: =F26*(1+C27) -> 105.18021 | G27: =MAX($F$2:F27) -> 110.56964 | H27: =(F27-G27)/F27 -> -0.051239964 | I27: =B27-K27 -> -28728.75 | K27: =-708+16792 -> 16084 | AK27: 975 | AN27: =K27/AK27 -> 16.49641 | AO27: =AO26+AN27 -> -255.92124
A28: 45483 | B28: 61934.25 | C28: =B28/'Clients Balance'!B28 -> 0.019842203 | E28: =C28*F27 -> 2.0870071 | F28: =F27*(1+C28) -> 107.26722 | G28: =MAX($F$2:F28) -> 110.56964 | H28: =(F28-G28)/F28 -> -0.030786881 | I28: =B28-K28 -> 61056.25 | K28: =-755+1633 -> 878 | AK28: 975 | AN28: =K28/AK28 -> 0.90051282 | AO28: =AO27+AN28 -> -255.02072
A29: 45484 | B29: 21988.75 | C29: =B29/'Clients Balance'!B29 -> 0.0070733064 | E29: =C29*F28 -> 0.75873391 | F29: =F28*(1+C29) -> 108.02595 | G29: =MAX($F$2:F29) -> 110.56964 | H29: =(F29-G29)/F29 -> -0.02354702 | I29: =B29-K29 -> 21988.75 | K29: 0 | AK29: 975 | AN29: =K29/AK29 -> 0 | AO29: =AO28+AN29 -> -255.02072
A30: 45485 | B30: 12094 | C30: =B30/'Clients Balance'!B30 -> 0.0038143852 | E30: =C30*F29 -> 0.4120526 | F30: =F29*(1+C30) -> 108.43801 | G30: =MAX($F$2:F30) -> 110.56964 | H30: =(F30-G30)/F30 -> -0.019657653 | I30: =B30-K30 -> -8754 | K30: 20848 | AK30: 975 | AN30: =K30/AK30 -> 21.382564 | AO30: =AO29+AN30 -> -233.63816
A31: 45488 | B31: 2925 | C31: =B31/'Clients Balance'!B31 -> 0.00091617609 | E31: =C31*F30 -> 0.099348309 | F31: =F30*(1+C31) -> 108.53736 | G31: =MAX($F$2:F31) -> 110.56964 | H31: =(F31-G31)/F31 -> -0.018724322 | I31: =B31-K31 -> 16360 | K31: =-1045-12390 -> -13435 | AK31: 975 | AN31: =K31/AK31 -> -13.779487 | AO31: =AO30+AN31 -> -247.41765
A32: 45489 | B32: 107071.25 | C32: =B32/'Clients Balance'!B32 -> 0.033410572 | E32: =C32*F31 -> 3.6262951 | F32: =F31*(1+C32) -> 112.16365 | G32: =MAX($F$2:F32) -> 112.16365 | H32: =(F32-G32)/F32 -> 0 | I32: =B32-K32 -> 148544.25 | K32: =-26263-15210 -> -41473 | AK32: 975 | AN32: =K32/AK32 -> -42.53641 | AO32: =AO31+AN32 -> -289.95406
A33: 45491 | B33: -40965 | C33: =B33/'Clients Balance'!B33 -> -0.012771085 | E33: =C33*F32 -> -1.4324515 | F33: =F32*(1+C33) -> 110.7312 | G33: =MAX($F$2:F33) -> 112.16365 | H33: =(F33-G33)/F33 -> -0.012936295 | I33: =B33-K33 -> -14997 | K33: =-64701+38733 -> -25968 | AK33: 975 | AN33: =K33/AK33 -> -26.633846 | AO33: =AO32+AN33 -> -316.5879
A34: 45492 | B34: 90556.75 | C34: =B34/'Clients Balance'!B34 -> 0.027319677 | E34: =C34*F33 -> 3.0251406 | F34: =F33*(1+C34) -> 113.75634 | G34: =MAX($F$2:F34) -> 113.75634 | H34: =(F34-G34)/F34 -> 0 | I34: =B34-K34 -> 72763.75 | K34: =17793 -> 17793 | AK34: 975 | AN34: =K34/AK34 -> 18.249231 | AO34: =AO33+AN34 -> -298.33867
A35: 45495 | B35: -72237 | C35: =B35/'Clients Balance'!B35 -> -0.022065569 | E35: =C35*F34 -> -2.5100983 | F35: =F34*(1+C35) -> 111.24624 | G35: =MAX($F$2:F35) -> 113.75634 | H35: =(F35-G35)/F35 -> -0.022563444 | I35: =B35-K35 -> -39654 | K35: =-18888-13695 -> -32583 | AK35: 975 | AN35: =K35/AK35 -> -33.418462 | AO35: =AO34+AN35 -> -331.75713
A36: 45496 | B36: -116609.75 | C36: =B36/'Clients Balance'!B36 -> -0.034660928 | E36: =C36*F35 -> -3.855898 | F36: =F35*(1+C36) -> 107.39034 | G36: =MAX($F$2:F36) -> 113.75634 | H36: =(F36-G36)/F36 -> -0.059279039 | I36: =B36-K36 -> -71046.75 | K36: =-8318-25142-12103 -> -45563 | AK36: 600 | AN36: =K36/AK36 -> -75.938333 | AO36: =AO35+AN36 -> -407.69547
A37: 45497 | B37: -114589.75 | C37: =B37/'Clients Balance'!B37 -> -0.034807888 | E37: =C37*F36 -> -3.7380311 | F37: =F36*(1+C37) -> 103.65231 | G37: =MAX($F$2:F37) -> 113.75634 | H37: =(F37-G37)/F37 -> -0.09748 | I37: =B37-K37 -> -114589.75 | K37: 0 | AK37: 975 | AN37: =K37/AK37 -> 0 | AO37: =AO36+AN37 -> -407.69547
A38: 45498 | B38: 62031.25 | C38: =B38/'Clients Balance'!B38 -> 0.019534615 | E38: =C38*F37 -> 2.024808 | F38: =F37*(1+C38) -> 105.67712 | G38: =MAX($F$2:F38) -> 113.75634 | H38: =(F38-G38)/F38 -> -0.076451926 | I38: =B38-K38 -> 64281.25 | K38: -2250 | AK38: 975 | AN38: =K38/AK38 -> -2.3076923 | AO38: =AO37+AN38 -> -410.00316
A39: 45499 | B39: 241007.25 | C39: =B39/'Clients Balance'!B39 -> 0.078738328 | E39: =C39*F38 -> 8.3208397 | F39: =F38*(1+C39) -> 113.99796 | G39: =MAX($F$2:F39) -> 113.99796 | H39: =(F39-G39)/F39 -> 0 | I39: =B39-K39 -> 46107.25 | K39: =137013+57887 -> 194900 | AK39: 800 | AN39: =K39/AK39 -> 243.625 | AO39: =AO38+AN39 -> -166.37816
A40: 45502 | B40: -85260 | C40: =B40/'Clients Balance'!B40 -> -0.027301595 | E40: =C40*F39 -> -3.1123262 | F40: =F39*(1+C40) -> 110.88563 | G40: =MAX($F$2:F40) -> 113.99796 | H40: =(F40-G40)/F40 -> -0.028067894 | I40: =B40-K40 -> -101851 | K40: 16591 | AK40: 500 | AN40: =K40/AK40 -> 33.182 | AO40: =AO39+AN40 -> -133.19616
...

Sheet Dec 25 Performance
A1: Date | B1: Cumm Capital | C1: Directional_1_Strategy_PNL | D1: Directional_2_Strategy_PNL | E1: NON_Directional_PNL | F1: 0Dte_PNL | G1: Total_PNL | H1: Cumm_PNL | I1: Drawdown | J1: Cumm pNL adjusted prev month
A2: ='PROP DAILY PNL'!A376 -> 45992 | B2: 128000 | C2: ='PROP DAILY PNL'!J376/$B$2/100 -> 0.0047592188 | D2: ='PROP DAILY PNL'!R376/$B$2/100 -> -0.0037075 | E2: ='PROP DAILY PNL'!Q376/$B$2/100 -> 0.0023203125 | F2: ='PROP DAILY PNL'!I376/$B$2/100 -> 0 | G2: =SUM(C2:F2) -> 0.0033720313 | H2: =G2 -> 0.0033720313 | I2: =IF(ISBLANK(J2),,J2-MAX($J$2:J2,0)) -> -0.034015938 | J2: =H2+'Nov 25 Performance'!I21 -> -0.034015938
A3: ='PROP DAILY PNL'!A377 -> 45993 | C3: ='PROP DAILY PNL'!J377/$B$2/100 -> 0.0033822656 | D3: ='PROP DAILY PNL'!R377/$B$2/100 -> 0.00046140625 | E3: ='PROP DAILY PNL'!Q377/$B$2/100 -> 0 | F3: ='PROP DAILY PNL'!I377/$B$2/100 -> 0.011873672 | G3: =SUM(C3:F3) -> 0.015717344 | H3: =H2+G3 -> 0.019089375 | I3: =IF(ISBLANK(J3),,J3-MAX($J$2:J3,0)) -> -0.018298594 | J3: =J2+G3 -> -0.018298594
A4: ='PROP DAILY PNL'!A378 -> 45994 | C4: ='PROP DAILY PNL'!J378/$B$2/100 -> -0.00029296875 | D4: ='PROP DAILY PNL'!R378/$B$2/100 -> 0.0047621875 | E4: ='PROP DAILY PNL'!Q378/$B$2/100 -> 0.0038810937 | F4: ='PROP DAILY PNL'!I378/$B$2/100 -> 0 | G4: =SUM(C4:F4) -> 0.0083503125 | H4: =H3+G4 -> 0.027439688 | I4: =IF(ISBLANK(J4),,J4-MAX($J$2:J4,0)) -> -0.0099482812 | J4: =J3+G4 -> -0.0099482812
A5: ='PROP DAILY PNL'!A379 -> 45995 | C5: ='PROP DAILY PNL'!J379/$B$2/100 -> 0.0016786719 | D5: ='PROP DAILY PNL'!R379/$B$2/100 -> 0.005160625 | E5: ='PROP DAILY PNL'!Q379/$B$2/100 -> 0 | F5: ='PROP DAILY PNL'!I379/$B$2/100 -> -0.0039028906 | G5: =SUM(C5:F5) -> 0.0029364063 | H5: =H4+G5 -> 0.030376094 | I5: =IF(ISBLANK(J5),,J5-MAX($J$2:J5,0)) -> -0.007011875 | J5: =J4+G5 -> -0.007011875
A6: ='PROP DAILY PNL'!A380 -> 45996 | C6: ='PROP DAILY PNL'!J380/$B$2/100 -> 0.00048570313 | D6: ='PROP DAILY PNL'!R380/$B$2/100 -> 0.00628125 | E6: ='PROP DAILY PNL'!Q380/$B$2/100 -> -0.0017196875 | F6: ='PROP DAILY PNL'!I380/$B$2/100 -> 0 | G6: =SUM(C6:F6) -> 0.0050472656 | H6: =H5+G6 -> 0.035423359 | I6: =IF(ISBLANK(J6),,J6-MAX($J$2:J6,0)) -> -0.0019646094 | J6: =J5+G6 -> -0.0019646094
A7: ='PROP DAILY PNL'!A381 -> 45999 | C7: ='PROP DAILY PNL'!J381/$B$2/100 -> 0.011570703 | D7: ='PROP DAILY PNL'!R381/$B$2/100 -> 0.0098290625 | E7: ='PROP DAILY PNL'!Q381/$B$2/100 -> 0.0011445312 | F7: ='PROP DAILY PNL'!I381/$B$2/100 -> 0 | G7: =SUM(C7:F7) -> 0.022544297 | H7: =H6+G7 -> 0.057967656 | I7: =IF(ISBLANK(J7),,J7-MAX($J$2:J7,0)) -> 0 | J7: =J6+G7 -> 0.020579687
A8: ='PROP DAILY PNL'!A382 -> 46000 | C8: ='PROP DAILY PNL'!J382/$B$2/100 -> -0.004709375 | D8: ='PROP DAILY PNL'!R382/$B$2/100 -> -0.00055953125 | E8: ='PROP DAILY PNL'!Q382/$B$2/100 -> 0 | F8: ='PROP DAILY PNL'!I382/$B$2/100 -> -0.0032278906 | G8: =SUM(C8:F8) -> -0.0084967969 | H8: =H7+G8 -> 0.049470859 | I8: =IF(ISBLANK(J8),,J8-MAX($J$2:J8,0)) -> -0.0084967969 | J8: =J7+G8 -> 0.012082891
A9: ='PROP DAILY PNL'!A383 -> 46001 | C9: ='PROP DAILY PNL'!J383/$B$2/100 -> -0.0037602344 | D9: ='PROP DAILY PNL'!R383/$B$2/100 -> -0.0024883594 | E9: ='PROP DAILY PNL'!Q383/$B$2/100 -> -0.0082109375 | F9: ='PROP DAILY PNL'!I383/$B$2/100 -> 0 | G9: =SUM(C9:F9) -> -0.014459531 | H9: =H8+G9 -> 0.035011328 | I9: =IF(ISBLANK(J9),,J9-MAX($J$2:J9,0)) -> -0.022956328 | J9: =J8+G9 -> -0.0023766406
A10: ='PROP DAILY PNL'!A384 -> 46002 | C10: ='PROP DAILY PNL'!J384/$B$2/100 -> 0.00041179687 | D10: ='PROP DAILY PNL'!R384/$B$2/100 -> -0.00099460938 | E10: ='PROP DAILY PNL'!Q384/$B$2/100 -> 0 | F10: ='PROP DAILY PNL'!I384/$B$2/100 -> -0.0018739062 | G10: =SUM(C10:F10) -> -0.0024567188 | H10: =H9+G10 -> 0.032554609 | I10: =IF(ISBLANK(J10),,J10-MAX($J$2:J10,0)) -> -0.025413047 | J10: =J9+G10 -> -0.0048333594
A11: ='PROP DAILY PNL'!A385 -> 46003 | C11: ='PROP DAILY PNL'!J385/$B$2/100 -> -0.0022890625 | D11: ='PROP DAILY PNL'!R385/$B$2/100 -> 0.0012896094 | E11: ='PROP DAILY PNL'!Q385/$B$2/100 -> 0.00098226563 | F11: ='PROP DAILY PNL'!I385/$B$2/100 -> 0 | G11: =SUM(C11:F11) -> -1.71875e-05 | H11: =H10+G11 -> 0.032537422 | I11: =IF(ISBLANK(J11),,J11-MAX($J$2:J11,0)) -> -0.025430234 | J11: =J10+G11 -> -0.0048505469
A12: ='PROP DAILY PNL'!A386 -> 46006 | C12: ='PROP DAILY PNL'!J386/$B$2/100 -> 0.00092234375 | D12: ='PROP DAILY PNL'!R386/$B$2/100 -> -0.0040625 | E12: ='PROP DAILY PNL'!Q386/$B$2/100 -> 0.0031875 | F12: ='PROP DAILY PNL'!I386/$B$2/100 -> 0 | G12: =SUM(C12:F12) -> 4.734375e-05 | H12: =H11+G12 -> 0.032584766 | I12: =IF(ISBLANK(J12),,J12-MAX($J$2:J12,0)) -> -0.025382891 | J12: =J11+G12 -> -0.0048032031
A13: ='PROP DAILY PNL'!A387 -> 46007 | C13: ='PROP DAILY PNL'!J387/$B$2/100 -> 0.001223125 | D13: ='PROP DAILY PNL'!R387/$B$2/100 -> -0.00042625 | E13: ='PROP DAILY PNL'!Q387/$B$2/100 -> 0 | F13: ='PROP DAILY PNL'!I387/$B$2/100 -> 0.010054375 | G13: =SUM(C13:F13) -> 0.01085125 | H13: =H12+G13 -> 0.043436016 | I13: =IF(ISBLANK(J13),,J13-MAX($J$2:J13,0)) -> -0.014531641 | J13: =J12+G13 -> 0.0060480469
A14: ='PROP DAILY PNL'!A388 -> 46008 | C14: ='PROP DAILY PNL'!J388/$B$2/100 -> 0.00179 | D14: ='PROP DAILY PNL'!R388/$B$2/100 -> 0.001888125 | E14: ='PROP DAILY PNL'!Q388/$B$2/100 -> 0.0044657813 | F14: ='PROP DAILY PNL'!I388/$B$2/100 -> 0 | G14: =SUM(C14:F14) -> 0.0081439062 | H14: =H13+G14 -> 0.051579922 | I14: =IF(ISBLANK(J14),,J14-MAX($J$2:J14,0)) -> -0.0063877344 | J14: =J13+G14 -> 0.014191953
... A24: ='PROP DAILY PNL'!A398 -> 46022 | C24: ='PROP DAILY PNL'!J398/$B$2/100 -> 0 | D24: ='PROP DAILY PNL'!R398/$B$2/100 -> 0 | E24: ='PROP DAILY PNL'!Q398/$B$2/100 -> 0 | F24: ='PROP DAILY PNL'!I398/$B$2/100 -> 0 | G24: =SUM(C24:F24) -> 0 | H24: =H23+G24 -> 0.064087695 | I24: =IF(ISBLANK(J24),,J24-MAX($J$2:J24,0)) -> -0.00084757813 | J24: =J23+G24 -> 0.026699727
A26: ='PROP DAILY PNL'!A400

Sheet Nov 25 Performance
A1: Date | B1: Cumm Capital | C1: Directional_1_Strategy_PNL | D1: Directional_2_Strategy_PNL | E1: NON_Directional_PNL | F1: 0Dte_PNL | G1: Total_PNL | H1: Cumm_PNL | I1: Drawdown
A2: ='PROP DAILY PNL'!A356 -> 45964 | B2: 128000 | C2: ='PROP DAILY PNL'!J356/$B$2/100 -> -0.0077914844 | D2: ='PROP DAILY PNL'!R356/$B$2/100 -> -0.0012023438 | E2: ='PROP DAILY PNL'!Q356/$B$2/100 -> 0.0031033594 | F2: ='PROP DAILY PNL'!I356/$B$2/100 -> 0 | G2: =SUM(C2:F2) -> -0.0058904687 | H2: =G2 -> -0.0058904687 | I2: =H2 -> -0.0058904687
A3: ='PROP DAILY PNL'!A357 -> 45965 | C3: ='PROP DAILY PNL'!J357/$B$2/100 -> 0.0093808594 | D3: ='PROP DAILY PNL'!R357/$B$2/100 -> 0.0044921875 | E3: ='PROP DAILY PNL'!Q357/$B$2/100 -> 0 | F3: ='PROP DAILY PNL'!I357/$B$2/100 -> 0.013676719 | G3: =SUM(C3:F3) -> 0.027549766 | H3: =G3+H2 -> 0.021659297 | I3: =H3 - MAX($H$2:H3) -> 0
A4: ='PROP DAILY PNL'!A358 -> 45966 | C4: ='PROP DAILY PNL'!J358/$B$2/100 -> 0 | D4: ='PROP DAILY PNL'!R358/$B$2/100 -> 0 | E4: ='PROP DAILY PNL'!Q358/$B$2/100 -> 0 | F4: ='PROP DAILY PNL'!I358/$B$2/100 -> 0 | G4: =SUM(C4:F4) -> 0 | H4: =G4+H3 -> 0.021659297 | I4: =H4 - MAX($H$2:H4) -> 0
A5: ='PROP DAILY PNL'!A359 -> 45967 | C5: ='PROP DAILY PNL'!J359/$B$2/100 -> -0.0018661719 | D5: ='PROP DAILY PNL'!R359/$B$2/100 -> 0.0025382813 | E5: ='PROP DAILY PNL'!Q359/$B$2/100 -> 0 | F5: ='PROP DAILY PNL'!I359/$B$2/100 -> -0.0020663281 | G5: =SUM(C5:F5) -> -0.0013942188 | H5: =G5+H4 -> 0.020265078 | I5: =H5 - MAX($H$2:H5) -> -0.0013942188
A6: ='PROP DAILY PNL'!A360 -> 45968 | C6: ='PROP DAILY PNL'!J360/$B$2/100 -> -0.0045658594 | D6: ='PROP DAILY PNL'!R360/$B$2/100 -> 0.0043863281 | E6: ='PROP DAILY PNL'!Q360/$B$2/100 -> -0.0049726562 | F6: ='PROP DAILY PNL'!I360/$B$2/100 -> 0 | G6: =SUM(C6:F6) -> -0.0051521875 | H6: =G6+H5 -> 0.015112891 | I6: =H6 - MAX($H$2:H6) -> -0.0065464063
A7: ='PROP DAILY PNL'!A361 -> 45971 | C7: ='PROP DAILY PNL'!J361/$B$2/100 -> -0.00089648438 | D7: ='PROP DAILY PNL'!R361/$B$2/100 -> -0.0027164063 | E7: ='PROP DAILY PNL'!Q361/$B$2/100 -> 0.0024765625 | F7: ='PROP DAILY PNL'!I361/$B$2/100 -> 0 | G7: =SUM(C7:F7) -> -0.0011363281 | H7: =G7+H6 -> 0.013976562 | I7: =H7 - MAX($H$2:H7) -> -0.0076827344
A8: ='PROP DAILY PNL'!A362 -> 45972 | C8: ='PROP DAILY PNL'!J362/$B$2/100 -> 0.0036400781 | D8: ='PROP DAILY PNL'!R362/$B$2/100 -> 0.0052739844 | E8: ='PROP DAILY PNL'!Q362/$B$2/100 -> 0 | F8: ='PROP DAILY PNL'!I362/$B$2/100 -> -0.009140625 | G8: =SUM(C8:F8) -> -0.0002265625 | H8: =G8+H7 -> 0.01375 | I8: =H8 - MAX($H$2:H8) -> -0.0079092969
A9: ='PROP DAILY PNL'!A363 -> 45973 | C9: ='PROP DAILY PNL'!J363/$B$2/100 -> 0.0022411719 | D9: ='PROP DAILY PNL'!R363/$B$2/100 -> -0.0024380469 | E9: ='PROP DAILY PNL'!Q363/$B$2/100 -> 0.0015621094 | F9: ='PROP DAILY PNL'!I363/$B$2/100 -> 0 | G9: =SUM(C9:F9) -> 0.0013652344 | H9: =G9+H8 -> 0.015115234 | I9: =H9 - MAX($H$2:H9) -> -0.0065440625
A10: ='PROP DAILY PNL'!A364 -> 45974 | C10: ='PROP DAILY PNL'!J364/$B$2/100 -> -0.00022851563 | D10: ='PROP DAILY PNL'!R364/$B$2/100 -> -0.010442656 | E10: ='PROP DAILY PNL'!Q364/$B$2/100 -> 0 | F10: ='PROP DAILY PNL'!I364/$B$2/100 -> -0.010365391 | G10: =SUM(C10:F10) -> -0.021036563 | H10: =G10+H9 -> -0.0059213281 | I10: =H10 - MAX($H$2:H10) -> -0.027580625
A11: ='PROP DAILY PNL'!A365 -> 45975 | C11: ='PROP DAILY PNL'!J365/$B$2/100 -> -0.0014707031 | D11: ='PROP DAILY PNL'!R365/$B$2/100 -> -0.013150469 | E11: ='PROP DAILY PNL'!Q365/$B$2/100 -> 0.004765625 | F11: ='PROP DAILY PNL'!I365/$B$2/100 -> 0 | G11: =SUM(C11:F11) -> -0.0098555469 | H11: =G11+H10 -> -0.015776875 | I11: =H11 - MAX($H$2:H11) -> -0.037436172
A12: ='PROP DAILY PNL'!A366 -> 45978 | C12: ='PROP DAILY PNL'!J366/$B$2/100 -> 0.00075609375 | D12: ='PROP DAILY PNL'!R366/$B$2/100 -> 0.0023657031 | E12: ='PROP DAILY PNL'!Q366/$B$2/100 -> -0.0002590625 | F12: ='PROP DAILY PNL'!I366/$B$2/100 -> 0 | G12: =SUM(C12:F12) -> 0.0028627344 | H12: =G12+H11 -> -0.012914141 | I12: =H12 - MAX($H$2:H12) -> -0.034573437
A13: ='PROP DAILY PNL'!A367 -> 45979 | C13: ='PROP DAILY PNL'!J367/$B$2/100 -> -0.002798125 | D13: ='PROP DAILY PNL'!R367/$B$2/100 -> 0.00030054687 | E13: ='PROP DAILY PNL'!Q367/$B$2/100 -> 0 | F13: ='PROP DAILY PNL'!I367/$B$2/100 -> 0.0095153125 | G13: =SUM(C13:F13) -> 0.0070177344 | H13: =G13+H12 -> -0.0058964062 | I13: =H13 - MAX($H$2:H13) -> -0.027555703
A14: ='PROP DAILY PNL'!A368 -> 45980 | C14: ='PROP DAILY PNL'!J368/$B$2/100 -> 0.0053027344 | D14: ='PROP DAILY PNL'!R368/$B$2/100 -> 0.00046195313 | E14: ='PROP DAILY PNL'!Q368/$B$2/100 -> -0.00314875 | F14: ='PROP DAILY PNL'!I368/$B$2/100 -> 0 | G14: =SUM(C14:F14) -> 0.0026159375 | H14: =G14+H13 -> -0.0032804687 | I14: =H14 - MAX($H$2:H14) -> -0.024939766
... A21: ='PROP DAILY PNL'!A375 -> 45989 | C21: ='PROP DAILY PNL'!J375/$B$2/100 -> -0.0024486719 | D21: ='PROP DAILY PNL'!R375/$B$2/100 -> -0.0036101563 | E21: ='PROP DAILY PNL'!Q375/$B$2/100 -> 0.0054107031 | F21: ='PROP DAILY PNL'!I375/$B$2/100 -> 0 | G21: =SUM(C21:F21) -> -0.000648125 | H21: =G21+H20 -> -0.015728672 | I21: =H21 - MAX($H$2:H21) -> -0.037387969
A22: ='PROP DAILY PNL'!A378 -> 45994

Sheet Oct 25 Performance 
A1: Date | B1: Cumm Capital | C1: Directional_1_Strategy_PNL | D1: Directional_2_Strategy_PNL | E1: NON_Directional_PNL | F1: 0Dte_PNL | G1: Total_PNL | H1: Cumm_PNL | I1: Drawdown
A2: ='PROP DAILY PNL'!A333 -> 45931 | B2: 13000000 | C2: ='PROP DAILY PNL'!J333/$B$2 -> 0.0098566923 | D2: ='PROP DAILY PNL'!R333/$B$2 -> 0.0040638462 | E2: ='PROP DAILY PNL'!Q333/$B$2 -> 0 | F2: ='PROP DAILY PNL'!I333/$B$2 -> 0.017064 | G2: =SUM(C2:F2) -> 0.030984538 | H2: =G2 -> 0.030984538 | I2: =(H2 - MAX($H$2:H2)) -> 0
A3: ='PROP DAILY PNL'!A334 -> 45932 | C3: ='PROP DAILY PNL'!J334/$B$2 -> 0 | D3: ='PROP DAILY PNL'!R334/$B$2 -> 0 | E3: ='PROP DAILY PNL'!Q334/$B$2 -> 0 | F3: ='PROP DAILY PNL'!I334/$B$2 -> 0 | G3: =SUM(C3:F3) -> 0 | H3: =H2+G3 -> 0.030984538 | I3: =(H3 - MAX($H$2:H3)) -> 0
A4: ='PROP DAILY PNL'!A335 -> 45933 | C4: ='PROP DAILY PNL'!J335/$B$2 -> 0.0026030769 | D4: ='PROP DAILY PNL'!R335/$B$2 -> -0.0045588462 | E4: ='PROP DAILY PNL'!Q335/$B$2 -> 0.0036946154 | F4: ='PROP DAILY PNL'!I335/$B$2 -> 0 | G4: =SUM(C4:F4) -> 0.0017388462 | H4: =H3+G4 -> 0.032723385 | I4: =(H4 - MAX($H$2:H4)) -> 0 | L4: Oct Performance
A5: ='PROP DAILY PNL'!A336 -> 45936 | C5: ='PROP DAILY PNL'!J336/$B$2 -> 0.0088303846 | D5: ='PROP DAILY PNL'!R336/$B$2 -> 0.0013413077 | E5: ='PROP DAILY PNL'!Q336/$B$2 -> -0.0058197692 | F5: ='PROP DAILY PNL'!I336/$B$2 -> 0 | G5: =SUM(C5:F5) -> 0.0043519231 | H5: =H4+G5 -> 0.037075308 | I5: =(H5 - MAX($H$2:H5)) -> 0
A6: ='PROP DAILY PNL'!A337 -> 45937 | C6: ='PROP DAILY PNL'!J337/$B$2 -> -0.0048615385 | D6: ='PROP DAILY PNL'!R337/$B$2 -> 0.00026384615 | E6: ='PROP DAILY PNL'!Q337/$B$2 -> 0 | F6: ='PROP DAILY PNL'!I337/$B$2 -> -0.0040769231 | G6: =SUM(C6:F6) -> -0.0086746154 | H6: =H5+G6 -> 0.028400692 | I6: =(H6 - MAX($H$2:H6)) -> -0.0086746154 | L6: Gross ROI | M6: =H24 -> 0.068891923 | O6: AVERAGE RETURN | P6: =AVERAGE(G:G) -> 0.002995301
A7: ='PROP DAILY PNL'!A338 -> 45938 | C7: ='PROP DAILY PNL'!J338/$B$2 -> -0.0041538462 | D7: ='PROP DAILY PNL'!R338/$B$2 -> 0.0026004615 | E7: ='PROP DAILY PNL'!Q338/$B$2 -> -0.0088076923 | F7: ='PROP DAILY PNL'!I338/$B$2 -> 0 | G7: =SUM(C7:F7) -> -0.010361077 | H7: =H6+G7 -> 0.018039615 | I7: =(H7 - MAX($H$2:H7)) -> -0.019035692 | L7: Charges | M7: 0.02 | O7: STD DEVIATION | P7: =STDEV(G:G) -> 0.011909351
A8: ='PROP DAILY PNL'!A339 -> 45939 | C8: ='PROP DAILY PNL'!J339/$B$2 -> -0.0022769231 | D8: ='PROP DAILY PNL'!R339/$B$2 -> 0.0018865385 | E8: ='PROP DAILY PNL'!Q339/$B$2 -> 0 | F8: ='PROP DAILY PNL'!I339/$B$2 -> -0.0083846154 | G8: =SUM(C8:F8) -> -0.008775 | H8: =H7+G8 -> 0.0092646154 | I8: =(H8 - MAX($H$2:H8)) -> -0.027810692 | L8: Net ROI | M8: =M6-M7 -> 0.048891923 | O8: Rf | P8: 0.000268
A9: ='PROP DAILY PNL'!A340 -> 45940 | D9: ='PROP DAILY PNL'!R340/$B$2 -> 0.002301 | E9: ='PROP DAILY PNL'!Q340/$B$2 -> 0.0065078462 | F9: ='PROP DAILY PNL'!I340/$B$2 -> 0 | G9: =SUM(C9:F9) -> 0.0088088462 | H9: =H8+G9 -> 0.018073462 | I9: =(H9 - MAX($H$2:H9)) -> -0.019001846 | L9: MAX DD | M9: =MIN(I:I) -> -0.027810692 | O9: Sharpe ratio | P9: =(P6-P8)/P7 -> 0.22900501
A10: ='PROP DAILY PNL'!A341 -> 45943 | C10: ='PROP DAILY PNL'!J341/$B$2 -> -0.0063484615 | D10: ='PROP DAILY PNL'!R341/$B$2 -> -0.001787 | E10: ='PROP DAILY PNL'!Q341/$B$2 -> 0.0064569231 | F10: ='PROP DAILY PNL'!I341/$B$2 -> 0 | G10: =SUM(C10:F10) -> -0.0016785385 | H10: =H9+G10 -> 0.016394923 | I10: =(H10 - MAX($H$2:H10)) -> -0.020680385 | L10: TOTAL WIN DAYS | M10: =COUNTIF(G:G,">0") -> 12
A11: ='PROP DAILY PNL'!A342 -> 45944 | C11: ='PROP DAILY PNL'!J342/$B$2 -> 0.0069507692 | D11: ='PROP DAILY PNL'!R342/$B$2 -> 0.0024615385 | E11: ='PROP DAILY PNL'!Q342/$B$2 -> 0 | F11: ='PROP DAILY PNL'!I342/$B$2 -> 0.0068471538 | G11: =SUM(C11:F11) -> 0.016259462 | H11: =H10+G11 -> 0.032654385 | I11: =(H11 - MAX($H$2:H11)) -> -0.0044209231 | L11: TOTAL LOSS DAYS | M11: =COUNTIF(G:G,"<0") -> 8
A12: ='PROP DAILY PNL'!A343 -> 45945 | C12: ='PROP DAILY PNL'!J343/$B$2 -> 0.0024005385 | D12: ='PROP DAILY PNL'!R343/$B$2 -> -0.00064469231 | E12: ='PROP DAILY PNL'!Q343/$B$2 -> 0.0010338462 | F12: ='PROP DAILY PNL'!I343/$B$2 -> 0 | G12: =SUM(C12:F12) -> 0.0027896923 | H12: =H11+G12 -> 0.035444077 | I12: =(H12 - MAX($H$2:H12)) -> -0.0016312308 | L12: Sharpe annualised | M12: =0.24*SQRT(252) -> 3.8098819
A13: ='PROP DAILY PNL'!A344 -> 45946 | C13: ='PROP DAILY PNL'!J344/$B$2 -> 0.0072847692 | D13: ='PROP DAILY PNL'!R344/$B$2 -> 0.00076153846 | E13: ='PROP DAILY PNL'!Q344/$B$2 -> 0 | F13: ='PROP DAILY PNL'!I344/$B$2 -> 0.025769231 | G13: =SUM(C13:F13) -> 0.033815538 | H13: =H12+G13 -> 0.069259615 | I13: =(H13 - MAX($H$2:H13)) -> 0
A14: ='PROP DAILY PNL'!A345 -> 45947 | C14: ='PROP DAILY PNL'!J345/$B$2 -> -0.00068361538 | D14: ='PROP DAILY PNL'!R345/$B$2 -> 0.0045216154 | E14: ='PROP DAILY PNL'!Q345/$B$2 -> -0.012076923 | F14: ='PROP DAILY PNL'!I345/$B$2 -> 0 | G14: =SUM(C14:F14) -> -0.0082389231 | H14: =H13+G14 -> 0.061020692 | I14: =(H14 - MAX($H$2:H14)) -> -0.0082389231
A15: ='PROP DAILY PNL'!A346 -> 45950 | C15: ='PROP DAILY PNL'!J346/$B$2 -> 0 | D15: ='PROP DAILY PNL'!R346/$B$2 -> 0.00049123077 | E15: ='PROP DAILY PNL'!Q346/$B$2 -> 0 | F15: ='PROP DAILY PNL'!I346/$B$2 -> -0.009 | G15: =SUM(C15:F15) -> -0.0085087692 | H15: =H14+G15 -> 0.052511923 | I15: =(H15 - MAX($H$2:H15)) -> -0.016747692
A16: ='PROP DAILY PNL'!A347 -> 45951 | C16: ='PROP DAILY PNL'!J347/$B$2 -> 0 | D16: ='PROP DAILY PNL'!R347/$B$2 -> 0 | E16: ='PROP DAILY PNL'!Q347/$B$2 -> 0 | F16: ='PROP DAILY PNL'!I347/$B$2 -> 0 | G16: =SUM(C16:F16) -> 0 | H16: =H15+G16 -> 0.052511923 | I16: =(H16 - MAX($H$2:H16)) -> -0.016747692
A17: ='PROP DAILY PNL'!A348 -> 45952 | C17: ='PROP DAILY PNL'!J348/$B$2 -> 0 | D17: ='PROP DAILY PNL'!R348/$B$2 -> 0 | E17: ='PROP DAILY PNL'!Q348/$B$2 -> 0 | F17: ='PROP DAILY PNL'!I348/$B$2 -> 0 | G17: =SUM(C17:F17) -> 0 | H17: =H16+G17 -> 0.052511923 | I17: =(H17 - MAX($H$2:H17)) -> -0.016747692
A18: ='PROP DAILY PNL'!A349 -> 45953 | C18: ='PROP DAILY PNL'!J349/$B$2 -> 0.0045709231 | D18: ='PROP DAILY PNL'!R349/$B$2 -> 0.0028709231 | E18: ='PROP DAILY PNL'!Q349/$B$2 -> 0 | F18: ='PROP DAILY PNL'!I349/$B$2 -> 0.0070786154 | G18: =SUM(C18:F18) -> 0.014520462 | H18: =H17+G18 -> 0.067032385 | I18: =(H18 - MAX($H$2:H18)) -> -0.0022272308
A19: ='PROP DAILY PNL'!A350 -> 45954 | C19: ='PROP DAILY PNL'!J350/$B$2 -> 0.0051904615 | D19: ='PROP DAILY PNL'!R350/$B$2 -> 0.0024412308 | E19: ='PROP DAILY PNL'!Q350/$B$2 -> -0.0028941538 | F19: ='PROP DAILY PNL'!I350/$B$2 -> 0 | G19: =SUM(C19:F19) -> 0.0047375385 | H19: =H18+G19 -> 0.071769923 | I19: =(H19 - MAX($H$2:H19)) -> 0
A20: ='PROP DAILY PNL'!A351 -> 45957 | C20: ='PROP DAILY PNL'!J351/$B$2 -> -7.9307692e-05 | D20: ='PROP DAILY PNL'!R351/$B$2 -> -0.00053246154 | E20: ='PROP DAILY PNL'!Q351/$B$2 -> 0.0051603077 | F20: ='PROP DAILY PNL'!I351/$B$2 -> 0 | G20: =SUM(C20:F20) -> 0.0045485385 | H20: =H19+G20 -> 0.076318462 | I20: =(H20 - MAX($H$2:H20)) -> 0
A21: ='PROP DAILY PNL'!A352 -> 45958 | C21: ='PROP DAILY PNL'!J352/$B$2 -> -0.0071974615 | D21: ='PROP DAILY PNL'!R352/$B$2 -> -0.0034762308 | E21: ='PROP DAILY PNL'!Q352/$B$2 -> 0 | F21: ='PROP DAILY PNL'!I352/$B$2 -> -0.0022231538 | G21: =SUM(C21:F21) -> -0.012896846 | H21: =H20+G21 -> 0.063421615 | I21: =(H21 - MAX($H$2:H21)) -> -0.012896846
A22: ='PROP DAILY PNL'!A353 -> 45959 | C22: ='PROP DAILY PNL'!J353/$B$2 -> 0.00039369231 | D22: ='PROP DAILY PNL'!R353/$B$2 -> 0.00038076923 | E22: ='PROP DAILY PNL'!Q353/$B$2 -> -0.0018796923 | F22: ='PROP DAILY PNL'!I353/$B$2 -> 0 | G22: =SUM(C22:F22) -> -0.0011052308 | H22: =H21+G22 -> 0.062316385 | I22: =(H22 - MAX($H$2:H22)) -> -0.014002077
A23: ='PROP DAILY PNL'!A354 -> 45960 | C23: ='PROP DAILY PNL'!J354/$B$2 -> 0.0024092308 | D23: ='PROP DAILY PNL'!R354/$B$2 -> 0.0027792308 | E23: ='PROP DAILY PNL'!Q354/$B$2 -> 0 | F23: ='PROP DAILY PNL'!I354/$B$2 -> -0.00023 | G23: =SUM(C23:F23) -> 0.0049584615 | H23: =H22+G23 -> 0.067274846 | I23: =(H23 - MAX($H$2:H23)) -> -0.0090436154
A24: ='PROP DAILY PNL'!A355 -> 45961 | C24: ='PROP DAILY PNL'!J355/$B$2 -> -0.00043553846 | D24: ='PROP DAILY PNL'!R355/$B$2 -> 0.0046312308 | E24: ='PROP DAILY PNL'!Q355/$B$2 -> -0.0025786154 | F24: ='PROP DAILY PNL'!I355/$B$2 -> 0 | G24: =SUM(C24:F24) -> 0.0016170769 | H24: =H23+G24 -> 0.068891923 | I24: =(H24 - MAX($H$2:H24)) -> -0.0074265385

Sheet Clients Balance
A1: Date | B1: NET Prop Account | C1: Abhishek S | D1: Radhika | E1: KARAN | F1: Pavan | G1: Rasul | H1: SIVA | I1: RAVI | J1: MAHESH | K1: JAGADISH | L1: Bharghav | M1: Kaushik | N1: MAHESH A | O1: Aayushi A | P1: Dishant | Q1: BHARATH | R1: NARESH
A2: 45446 | B2: =SUM(C2:E2) -> 3056448.9 | C2: 2000000 | D2: 522572.87 | E2: 533876
A3: 45447 | B3: =SUM(C3:E3) -> 3139071.1 | C3: =C2+Sheet!C2 -> 2054064.2 | D3: =D2+Sheet!D2 -> 536699.12 | E3: =E2+Sheet!E2 -> 548307.79
A4: 45448 | B4: =SUM(C4:E4) -> 3294831.1 | C4: =C3+Sheet!C3 -> 2155986.4 | D4: =D3+Sheet!D3 -> 563330 | E4: =E3+Sheet!E3 -> 575514.7
A5: 45449 | B5: =SUM(C5:E5) -> 3281158.6 | C5: =C4+Sheet!C4 -> 2147039.8 | D5: =D4+Sheet!D4 -> 560992.36 | E5: =E4+Sheet!E4 -> 573126.5
A6: 45450 | B6: =SUM(C6:E6) -> 3287065.6 | C6: =C5+Sheet!C5 -> 2150905 | D6: =D5+Sheet!D5 -> 562002.31 | E6: =E5+Sheet!E5 -> 574158.29
A7: 45453 | B7: =SUM(C7:E7) -> 3319363.6 | C7: =C6+Sheet!C6 -> 2172039.4 | D7: =D6+Sheet!D6 -> 567524.42 | E7: =E6+Sheet!E6 -> 579799.84
A8: 45454 | B8: =SUM(C8:E8) -> 3351432.1 | C8: =C7+Sheet!C7 -> 2193023.5 | D8: =D7+Sheet!D7 -> 573007.3 | E8: =E7+Sheet!E7 -> 585401.31
A9: 45455 | B9: =SUM(C9:E9) -> 3351969.1 | C9: =C8+Sheet!C8 -> 2193374.9 | D9: =D8+Sheet!D8 -> 573099.11 | E9: =E8+Sheet!E8 -> 585495.11
A10: 45456 | B10: =SUM(C10:E10) -> 3343665.1 | C10: =C9+Sheet!C9 -> 2187941.1 | D10: =D9+Sheet!D9 -> 571679.34 | E10: =E9+Sheet!E9 -> 584044.63
A11: 45457 | B11: =SUM(C11:E11) -> 3353408.4 | C11: =C10+Sheet!C10 -> 2194316.7 | D11: =D10+Sheet!D10 -> 573345.18 | E11: =E10+Sheet!E10 -> 585746.51
A12: 45461 | B12: =SUM(C12:E12) -> 3353893.9 | C12: =C11+Sheet!C11 -> 2194634.4 | D12: =D11+Sheet!D11 -> 573428.19 | E12: =E11+Sheet!E11 -> 585831.31
A13: 45462 | B13: =SUM(C13:E13) -> 3360276.1 | C13: =C12+Sheet!C12 -> 2198810.6 | D13: =D12+Sheet!D12 -> 574519.39 | E13: =E12+Sheet!E12 -> 586946.11
A14: 45463 | B14: =SUM(C14:E14) -> 3302473.4 | C14: =C13+Sheet!C13 -> 2160987.2 | D14: =D13+Sheet!D13 -> 564636.63 | E14: =E13+Sheet!E13 -> 576849.59
... A21: 45472 | B21: =SUM(C21:E21) -> 3179069.6 | C21: =C20+Sheet!C20 -> 2080237.4 | D21: =D20+Sheet!D20 -> 543537.81 | E21: =E20+Sheet!E20 -> 555294.41
A22: 45474 | B22: =C22+D22+E22 -> 3074680.1 | C22: =Monthly!F4 -> 1994647.4 | D22: =Monthly!M4 -> 534238.63 | E22: =Monthly!S4 -> 545794.09
A23: 45475 | B23: =C23+D23+E23 -> 3064017.9 | C23: =C22+Sheet!C21 -> 1987608.2 | D23: =D22+Sheet!D21 -> 532430.86 | E23: =E22+Sheet!E21 -> 543978.82
A24: 45476 | B24: =C24+D24+E24 -> 3039333.9 | C24: =C23+Sheet!C22 -> 1971566.4 | D24: =D23+Sheet!D22 -> 528148.82 | E24: =E23+Sheet!E22 -> 539618.7
A25: 45477 | B25: =C25+D25+E25 -> 3151837.7 | C25: =C24+Sheet!C23 -> 2044546.9 | D25: =D24+Sheet!D23 -> 547698.47 | E25: =E24+Sheet!E23 -> 559592.36
A26: 45478 | B26: =C26+D26+E26 -> 3191716.4 | C26: =C25+Sheet!C24 -> 2070415.6 | D26: =D25+Sheet!D24 -> 554628.25 | E26: =E25+Sheet!E24 -> 566672.64
A27: 45481 | B27: =C27+D27+E27 -> 3165971.9 | C27: =C26+Sheet!C25 -> 2053715.5 | D27: =D26+Sheet!D25 -> 550154.59 | E27: =E26+Sheet!E25 -> 562101.84
A28: 45482 | B28: =C28+D28+E28 -> 3121339.4 | C28: =C27+Sheet!C26 -> 2024763.1 | D28: =D27+Sheet!D26 -> 542398.75 | E28: =E27+Sheet!E26 -> 554177.57
A29: 45483 | B29: =C29+D29+E29 -> 3108694.7 | C29: =C28+Sheet!C27 -> 2016560.7 | D29: =D28+Sheet!D27 -> 540201.46 | E29: =E28+Sheet!E27 -> 551932.56
A30: 45484 | B30: =C30+D30+E30 -> 3170628.9 | C30: =C29+Sheet!C28 -> 2056736.4 | D30: =D29+Sheet!D28 -> 550963.85 | E30: =E29+Sheet!E28 -> 562928.66
A31: 45485 | B31: =C31+D31+E31 -> 3192617.7 | C31: =C30+Sheet!C29 -> 2071000.2 | D31: =D30+Sheet!D29 -> 554784.86 | E31: =E30+Sheet!E29 -> 566832.65
A32: 45488 | B32: =C32+D32+E32 -> 3204711.7 | C32: =C31+Sheet!C30 -> 2078845.4 | D32: =D31+Sheet!D30 -> 556886.45 | E32: =E31+Sheet!E30 -> 568979.88
A33: 45489 | B33: =C33+D33+E33 -> 3207636.7 | C33: =C32+Sheet!C31 -> 2080742.8 | D33: =D32+Sheet!D31 -> 557394.73 | E33: =E32+Sheet!E31 -> 569499.2
A34: 45491 | B34: =C34+D34+E34 -> 3314707.9 | C34: =C33+Sheet!C32 -> 2150198.2 | D34: =D33+Sheet!D32 -> 576000.62 | E34: =E33+Sheet!E32 -> 588509.14
A35: 45492 | B35: =C35+D35+E35 -> 3273742.9 | C35: =C34+Sheet!C33 -> 2123624.8 | D35: =D34+Sheet!D33 -> 568882.09 | E35: =E34+Sheet!E33 -> 581236.02
A36: 45495 | B36: =C36+D36+E36 -> 3364299.7 | C36: =C35+Sheet!C34 -> 2182367.6 | D36: =D35+Sheet!D34 -> 584618.24 | E36: =E35+Sheet!E34 -> 597313.9 | F36: ATH
A37: 45496 | B37: =C37+D37+E37 -> 3292062.7 | C37: =C36+Sheet!C35 -> 2135508.6 | D37: =D36+Sheet!D35 -> 572065.53 | E37: =E36+Sheet!E35 -> 584488.59
A38: 45497 | B38: =C38+D38+E38 -> 3175452.9 | C38: =C37+Sheet!C36 -> 2059865.7 | D38: =D37+Sheet!D36 -> 551802.12 | E38: =E37+Sheet!E36 -> 563785.14
A39: 45498 | B39: =C39+D39+E39 -> 3060863.2 | C39: =C38+Sheet!C37 -> 1985533.1 | D39: =D38+Sheet!D37 -> 531889.73 | E39: =E38+Sheet!E37 -> 543440.33
A40: 45499 | B40: =C40+D40+E40 -> 3122894.4 | C40: =C39+Sheet!C38 -> 2025771.8 | D40: =D39+Sheet!D38 -> 542668.97 | E40: =E39+Sheet!E38 -> 554453.65
A41: 45502 | B41: =C41+D41+E41 -> 3363901.7 | C41: =C40+Sheet!C39 -> 2182109.4 | D41: =D40+Sheet!D39 -> 584549.08 | E41: =E40+Sheet!E39 -> 597243.23
A42: 45503 | B42: =C42+D42+E42 -> 3278641.7 | C42: =C41+Sheet!C40 -> 2126802.6 | D42: =D41+Sheet!D40 -> 569733.35 | E42: =E41+Sheet!E40 -> 582105.76
A43: 45504 | B43: =C43+D43+E43 -> 3167301.7 | C43: =C42+Sheet!C41 -> 2054578.1 | D43: =D42+Sheet!D41 -> 550385.67 | E43: =E42+Sheet!E41 -> 562337.93
A44: 45505 | B44: =C44+D44+E44 -> 3114578.2 | C44: =C43+Sheet!C42 -> 2020377.2 | D44: =D43+Sheet!D42 -> 541223.84 | E44: =E43+Sheet!E42 -> 552977.14
A45: 45506 | B45: =C45+D45+E45 -> 2993789.9 | C45: =Monthly!F5 -> 1924607.9 | D45: =Monthly!M5 -> 528871.32 | E45: =Monthly!S5 -> 540310.68
A46: 45509 | B46: =C46+D46+E46 -> 3094367.9 | C46: =C45+Sheet!C43 -> 1989851.2 | D46: =D45+Sheet!D43 -> 546348.87 | E46: =E45+Sheet!E43 -> 558167.78
...

Sheet Monthly
A1: Month | C1: Gross PNL | D1: Charges total | E1: Net PNL | F1: Abhishek | M1: Radhika | S1: Karan | Y1: Pavan | AE1: Rasul | AK1: SIVA | AQ1: RAVI | AW1: MAHESH | BC1: JAGADISH | BI1: BHARGHAV | BO1: KAUSHIK | BU1: MAHESH A | CA1: AAYUSHI A | CG1: Dishant | CM1: BHARATH | CS1: NARESH
B2: Start DATE of Month | F2: Open | G2: Profit | H2: charges | I2: Close | J2: Salary | K2: Deposit/Withdrawl | L2: % Return Net | M2: Open | N2: Profit | O2: charges | P2: Close | Q2: Deposit/Withdrawl | R2: % Return Net | S2: Open | T2: Profit | U2: Charges | V2: Close | W2: Deposit/Withdrawl | X2: % Return Net | Y2: Open | Z2: Profit | AA2: Charges | AB2: Close | AC2: Deposit/Withdrawl | AD2: % Return Net | AE2: Open | AF2: Profit | AG2: Charges | AH2: Close | AI2: Deposit/Withdrawl | AJ2: % Return Net | AK2: Open | AL2: Profit | AM2: Charges | AN2: Close | AO2: Deposit/Withdrawl | AP2: % Return Net | AQ2: Open | AR2: Profit | AS2: Charges | AT2: Close | AU2: Deposit/Withdrawl | AV2: % Return Net | AW2: Open | AX2: Profit | AY2: Charges | AZ2: Close | BA2: Deposit/Withdrawl | BB2: % Return Net | BC2: Open | BD2: Profit | BE2: Charges | BF2: Close | BG2: Deposit/Withdrawl | BH2: % Return Net | BI2: Open | BJ2: Profit | BK2: Charges | BL2: Close | BM2: Deposit/Withdrawl | BN2: % Return Net | BO2: Open | BP2: Profit | BQ2: Charges | BR2: Close | BS2: Deposit/Withdrawl | BT2: % Return Net | BU2: Open | BV2: Profit | BW2: Charges | BX2: Close | BY2: Deposit/Withdrawl | BZ2: % Return Net | CA2: Open | CB2: Profit | CC2: Charges | CD2: Close | CE2: Deposit/Withdrawl | CF2: % Return Net | CG2: Open | CH2: Profit | CI2: Charges | CJ2: Close | CK2: Deposit/Withdrawl | CL2: % Return Net | CM2: Open | CN2: Profit | CO2: Charges | CP2: Close | CQ2: Deposit/Withdrawl | CR2: % Return Net | CS2: Open | CT2: Profit | CU2: Charges | CV2: Close | CW2: Deposit/Withdrawl | CX2: % Return Net | CY2: Total Open capital | CZ2: Leverage Capital | DA2: Working Capital (70%)
A3: 45467 | B3: =DATE(2024,6,1) -> 45444 | C3: 147704 | D3: =Charges!H2 -> 79472.756 | E3: =C3-D3 -> 68231.244 | F3: ='Clients Balance'!C2 -> 2000000 | G3: =E3*F3/CY3 -> 44647.398 | H3: - | I3: =F3+G3 -> 2044647.4 | J3: 50000 | K3: 0 | L3: =(I3-F3)/F3*100 -> 2.2323699 | M3: ='Clients Balance'!D2 -> 522572.87 | N3: =E3*M3/CY3 -> 11665.759 | O3: - | P3: =M3+N3 -> 534238.63 | Q3: 0 | R3: =(P3-M3)/M3*100 -> 2.2323699 | S3: ='Clients Balance'!E2 -> 533876 | T3: =E3*S3/CY3 -> 11918.087 | U3: - | V3: =S3+T3 -> 545794.09 | W3: 0 | X3: =(V3-S3)/S3*100 -> 2.2323699 | CY3: =F3+M3+S3 -> 3056448.9
A4: 45497 | B4: =EDATE(B3,1) -> 45474 | C4: =SUM('PROP DAILY PNL'!B21:B42) -> 39209.75 | D4: =Charges!H4 -> 70100 | E4: =C4-D4 -> -30890.25 | F4: =I3-50000 -> 1994647.4 | G4: =E4*F4/CY4 -> -20039.534 | H4: - | I4: =F4+G4 -> 1974607.9 | J4: 50000 | K4: 0 | L4: =(I4-F4)/F4*100 -> -1.0046655 | M4: =P3 -> 534238.63 | N4: =E4*M4/CY4 -> -5367.3111 | O4: - | P4: =M4+N4 -> 528871.32 | Q4: 0 | R4: =(P4-M4)/M4*100 -> -1.0046655 | S4: =V3 -> 545794.09 | T4: =E4*S4/CY4 -> -5483.4048 | U4: - | V4: =S4+T4 -> 540310.68 | W4: 0 | X4: =(V4-S4)/S4*100 -> -1.0046655 | CY4: =F4+M4+S4 -> 3074680.1
A5: 45528 | B5: =EDATE(B4,1) -> 45505 | C5: =SUM('PROP DAILY PNL'!B43:B63) -> 707933.75 | D5: =Charges!H6 -> 75613 | E5: =C5-D5 -> 632320.75 | F5: =I4-50000 -> 1924607.9 | G5: =E5*F5/CY5 -> 406497.97 | H5: - | I5: =F5+G5 -> 2331105.8 | J5: 50000 | K5: 400000 | L5: =(I5-F5)/F5*100 -> 21.12108 | M5: =P4 -> 528871.32 | N5: =E5*M5/CY5 -> 111703.33 | O5: - | P5: =M5+N5 -> 640574.65 | Q5: 0 | R5: =(P5-M5)/M5*100 -> 21.12108 | S5: =V4 -> 540310.68 | T5: =E5*S5/CY5 -> 114119.45 | U5: - | V5: =S5+T5 -> 654430.13 | W5: 250000 | X5: =(V5-S5)/S5*100 -> 21.12108 | CY5: =F5+M5+S5 -> 2993789.9
A6: 45559 | B6: =EDATE(B5,1) -> 45536 | C6: =SUM('PROP DAILY PNL'!B64:B84) -> 1234853.2 | D6: =Charges!H8 -> 100168 | E6: =C6-D6 -> 1134685.2 | F6: =I5-50000-50000-15000+K5 -> 2616105.8 | G6: =SUM(Sheet!C64:C84) -> 776356.86 | H6: =Charges!I8 -> 62975.997 | I6: =F6+G6-H6 -> 3329486.7 | J6: 50000 | K6: 500000 | L6: =(I6-F6)/F6*100 -> 27.268808 | M6: =P5 -> 640574.65 | N6: =SUM(Sheet!D64:D84) -> 190097.25 | O6: =Charges!K8 -> 15420.182 | P6: =M6+N6-O6 -> 815251.72 | Q6: 0 | R6: =(P6-M6)/M6*100 -> 27.268808 | S6: =V5+W5 -> 904430.13 | T6: =SUM(Sheet!E64:E84) -> 268399.14 | U6: =Charges!M8 -> 21771.822 | V6: =S6+T6-U6 -> 1151057.4 | X6: =(V6-S6)/S6*100 -> 27.268808 | CY6: =F6+M6+S6 -> 4161110.6
A7: 45589 | B7: =EDATE(B6,1) -> 45566 | C7: =SUM('PROP DAILY PNL'!B85:B106) -> 182541.5 | D7: =Charges!H10 -> 182386 | E7: =C7-D7 -> 155.5 | F7: =I6-50000+K6 -> 3779486.7 | G7: =SUM(Sheet!C85:C106) -> 120072.69 | H7: =Charges!I10 -> 119970.41 | I7: =F7+G7-H7 -> 3779589 | J7: 50000 | K7: 0 | L7: =(I7-F7)/F7*100 -> 0.0027063266 | M7: =P6 -> 815251.72 | N7: =SUM(Sheet!D85:D106) -> 25900.202 | O7: =Charges!K10 -> 25878.138 | P7: =M7+N7-O7 -> 815273.79 | Q7: 0 | R7: =(P7-M7)/M7*100 -> 0.0027063266 | S7: =V6 -> 1151057.4 | T7: =SUM(Sheet!E85:E106) -> 36568.607 | U7: =Charges!M10 -> 36537.456 | V7: =S7+T7-U7 -> 1151088.6 | W7: 0 | X7: =(V7-S7)/S7*100 -> 0.0027063266 | CY7: =F7+M7+S7 -> 5745795.9
A8: 45620 | B8: =EDATE(B7,1) -> 45597 | C8: =SUM('PROP DAILY PNL'!B107:B124) -> 564849 | D8: =Charges!H12 -> 109026 | E8: =C8-D8 -> 455823 | F8: =I7-50000 -> 3729589 | G8: =SUM(Sheet!C107:C124) -> 370742.45 | H8: =Charges!I12 -> 71403.448 | I8: =F8+G8-H8 -> 4028928 | J8: 50000 | K8: - | L8: =(I8-F8)/F8*100 -> 8.0260588 | M8: =P7 -> 815273.79 | N8: =SUM(Sheet!D107:D124) -> 80478.543 | O8: =Charges!K12 -> 15598.691 | P8: =M8+N8-O8 -> 880153.64 | Q8: 0 | R8: =(P8-M8)/M8*100 -> 7.9580446 | S8: =V7 -> 1151088.6 | T8: =SUM(Sheet!E107:E124) -> 113628 | U8: =Charges!M12 -> 22023.86 | V8: =S8+T8-U8 -> 1242692.7 | W8: 0 | X8: =(V8-S8)/S8*100 -> 7.9580446 | CY8: =F8+M8+S8 -> 5695951.4
A9: 45650 | B9: =EDATE(B8,1) -> 45627 | C9: =sum(Sheet!B125:B145) -> 268802.25 | D9: =Charges!H14 -> 169070 | E9: =C9-D9 -> 99732.25 | F9: =I8-50000 -> 3978928 | G9: =SUM(Sheet!C125:C145) -> 175119.12 | H9: =Charges!I14 -> 110249.46 | I9: =F9+G9-H9 -> 4043797.6 | J9: 50000 | K9: 500000 | L9: =(I9-F9)/F9*100 -> 1.63033 | M9: =P8 -> 880153.64 | N9: =SUM(Sheet!D125:D145) -> 38841.975 | O9: =Charges!K14 -> 24387.591 | P9: =M9+N9-O9 -> 894608.02 | Q9: 125000 | R9: =(P9-M9)/M9*100 -> 1.642257 | S9: =V8 -> 1242692.7 | T9: =SUM(Sheet!E125:E145) -> 54841.154 | U9: =Charges!M14 -> 34432.945 | V9: =S9+T9-U9 -> 1263101 | W9: 0 | X9: =(V9-S9)/S9*100 -> 1.642257 | CY9: =F9+M9+S9 -> 6101774.4
A10: 45681 | B10: =EDATE(B9,1) -> 45658 | C10: =SUM(Sheet!B146:B168) -> 916672.5 | D10: =Charges!H16 -> 253025 | E10: =C10-D10 -> 663647.5 | F10: =I9-50000+K9 -> 4493797.6 | G10: =SUM(Sheet!C146:C168) -> 460612.91 | H10: =Charges!I16+Charges!J16 -> 133888.64 | I10: =F10+G10-H10 -> 4820521.9 | J10: 50000 | K10: 200000 | L10: =(I10-F10)/F10*100 -> 7.2705603 | M10: =P9+Q9 -> 1019608 | N10: =SUM(Sheet!D146:D168) -> 104509.52 | O10: =Charges!K16+Charges!L16 -> 30378.299 | P10: =M10+N10-O10 -> 1093739.2 | R10: =(P10-M10)/M10*100 -> 7.2705603 | S10: =V9 -> 1263101 | T10: =SUM(Sheet!E146:E168) -> 129467.47 | U10: =Charges!M16+Charges!N16 -> 37632.951 | V10: =S10+T10-U10 -> 1354935.5 | W10: 0 | X10: =(V10-S10)/S10*100 -> 7.2705603 | Y10: ='Clients Balance'!F152 -> 1666666 | Z10: =SUM(Sheet!F146:F168) -> 170832.76 | AA10: =Charges!O16+Charges!P16 -> 52660.341 | AB10: =Y10+Z10-AA10 -> 1784838.4 | AC10: 0 | AD10: =(AB10-Y10)/Y10*100 -> 7.0903482 | AE10: ='Clients Balance'!G152 -> 500000 | AF10: =SUM(Sheet!G146:G168) -> 51249.849 | AG10: =Charges!Q16+Charges!R16 -> 15798.106 | AH10: =AE10+AF10-AG10 -> 535451.74 | AI10: 0 | AJ10: =(AH10-AE10)/AE10*100 -> 7.0903487 | CY10: =F10+M10+S10+Y10+AE10 -> 8943172.6
A11: 45712 | B11: =EDATE(B10,1) -> 45689 | C11: =SUM(Sheet!B169:B188) -> 607092.5 | D11: =Charges!H18+Charges!P18+Charges!R18+Charges!T18 -> 261128.22 | E11: =C11-D11 -> 345964.28 | F11: =I10-50000+K10 -> 4970521.9 | G11: =SUM(Sheet!C169:C188) -> 260375.93 | H11: =Charges!I18+Charges!J18 -> 103398.08 | I11: =F11+G11-H11 -> 5127499.8 | J11: 50000 | K11: 500000 | L11: =(I11-F11)/F11*100 -> 3.1581765 | M11: =P10 -> 1093739.2 | N11: =SUM(Sheet!D169:D188) -> 57043.051 | O11: =Charges!K18+Charges!L18 -> 23020.213 | P11: =M11+N11-O11 -> 1127762.1 | Q11: 0 | R11: =(P11-M11)/M11*100 -> 3.1106901 | S11: =V10 -> 1354935.5 | T11: =SUM(Sheet!E169:E188) -> 70665.497 | U11: =Charges!M18+Charges!N18 -> 28517.668 | V11: =S11+T11-U11 -> 1397083.3 | W11: -250000 | X11: =(V11-S11)/S11*100 -> 3.110689 | Y11: =AB10 -> 1784838.4 | Z11: =SUM(Sheet!F169:F188) -> 93086.748 | AA11: =Charges!O18+Charges!P18 -> 44370.45 | AB11: =Y11+Z11-AA11 -> 1833554.7 | AC11: 0 | AD11: =(AB11-Y11)/Y11*100 -> 2.7294515 | AE11: =AH10 -> 535451.74 | AF11: =SUM(Sheet!G169:G188) -> 27926.036 | AG11: =Charges!Q18+Charges!R18 -> 13311.137 | AH11: =AE11+AF11-AG11 -> 550066.64 | AI11: 333333 | AJ11: =(AH11-AE11)/AE11*100 -> 2.729452 | AK11: ='Clients Balance'!H177 -> 1666666 | AL11: =SUM(Sheet!H169:H188) -> 97995.24 | AM11: =Charges!S18+Charges!T18 -> 40093.539 | AN11: =AK11+AL11-AM11 -> 1724567.7 | AO11: 0 | AP11: =(AN11-AK11)/AK11*100 -> 3.4741034 | CY11: =F11+M11+S11+Y11+AE11+AK11 -> 11406153
A12: 45740 | B12: =EDATE(B11,1) -> 45717 | C12: =sum('PROP DAILY PNL'!B189:B207) -> 1003418.8 | D12: =Charges!H19 -> 260251 | E12: =C12-D12 -> 743167.75 | F12: =I11-J11+K11 -> 5577499.8 | G12: =SUMIFS(Sheet!C:C,Sheet!A:A, ">="&B12,Sheet!A:A, "<="&EOMONTH(B12,0)) -> 457391.03 | H12: =Charges!I19+Charges!J19 -> 118445.55 | I12: =F12+G12-H12 -> 5916445.2 | J12: 150000 | K12: 1100000 | L12: =(I12-F12)/F12*100 -> 6.0770148 | M12: =P11 -> 1127762.1 | N12: =SUMIFS(Sheet!D:D,Sheet!A:A, ">="&B12,Sheet!A:A, "<="&EOMONTH(B12,0)) -> 92553.018 | O12: =Charges!K19+Charges!L19 -> 23950.798 | P12: =M12+N12-O12 -> 1196364.3 | Q12: -100000 | R12: =(P12-M12)/M12*100 -> 6.0830402 | S12: =V11+W11 -> 1147083.3 | T12: =SUMIFS(Sheet!E:E,Sheet!A:A, ">="&B12,Sheet!A:A, "<="&EOMONTH(B12,0)) -> 95100.663 | U12: =Charges!M19+Charges!N19 -> 24379.004 | V12: =S12+T12-U12 -> 1217805 | W12: -150000 | X12: =(V12-S12)/S12*100 -> 6.1653464 | Y12: =AB11 -> 1833554.7 | Z12: =SUMIFS(Sheet!F:F,Sheet!A:A, ">="&B12,Sheet!A:A, "<="&EOMONTH(B12,0)) -> 150502.09 | AA12: =Charges!O19+Charges!P19 -> 38940.525 | AB12: =Y12+Z12-AA12 -> 1945116.3 | AC12: 0 | AD12: =(AB12-Y12)/Y12*100 -> 6.0844417 | AE12: =AH11+AI11 -> 883399.64 | AF12: =SUMIFS(Sheet!G:G,Sheet!A:A, ">="&B12,Sheet!A:A, "<="&EOMONTH(B12,0)) -> 67596.631 | AG12: =Charges!R19+Charges!Q19 -> 17911.827 | AH12: =AE12+AF12-AG12 -> 933084.45 | AI12: 0 | AJ12: =(AH12-AE12)/AE12*100 -> 5.6242726 | AK12: =AN11 -> 1724567.7 | AL12: =SUMIFS(Sheet!H:H,Sheet!A:A, ">="&B12,Sheet!A:A, "<="&EOMONTH(B12,0)) -> 141425.7 | AM12: =Charges!T19+Charges!S19 -> 36623.466 | AN12: =AK12+AL12-AM12 -> 1829369.9 | AO12: =1666666+972558 -> 2639224 | AP12: =(AN12-AK12)/AK12*100 -> 6.0770148 | CY12: =F12+M12+S12+Y12+AE12+AK12 -> 12293867
A13: 45772 | B13: =EDATE(B12,1) -> 45748 | C13: =sum('PROP DAILY PNL'!B208:B226) -> 269920.5 | D13: =Charges!H20 -> 390584 | E13: =C13-D13 -> -120663.5 | F13: =I12-J12+K12 -> 6866445.2 | G13: =SUMIFS(Sheet!C:C,Sheet!A:A, ">="&B13,Sheet!A:A, "<="&EOMONTH(B13,0)) -> 69209.203 | H13: =Charges!I20+Charges!J20 -> 135609.67 | I13: =F13+G13-H13 -> 6800044.8 | J13: 150000 | K13: 109856 | L13: =(I13-F13)/F13*100 -> -0.96702829 | M13: =P12+Q12 -> 1096364.3 | N13: =SUMIFS(Sheet!D:D,Sheet!A:A, ">="&B13,Sheet!A:A, "<="&EOMONTH(B13,0)) -> 11050.623 | O13: =Charges!K20+Charges!L20 -> 21652.776 | P13: =M13+N13-O13 -> 1085762.1 | Q13: 375000 | R13: =(P13-M13)/M13*100 -> -0.96702829 | S13: =V12+W12 -> 1067805 | T13: =SUMIFS(Sheet!E:E,Sheet!A:A, ">="&B13,Sheet!A:A, "<="&EOMONTH(B13,0)) -> 10762.764 | U13: =Charges!M20+Charges!N20 -> 21088.74 | V13: =S13+T13-U13 -> 1057479 | W13: 150000 | X13: =(V13-S13)/S13*100 -> -0.96702829 | Y13: ACCOUNT CLOSED | Z13: =SUMIFS(Sheet!F:F,Sheet!A:A, ">="&B13,Sheet!A:A, "<="&EOMONTH(B13,0)) -> 0 | AA13: =Charges!O20+Charges!P20 -> 0 | AD13: =(AB13-Y13)/Y13*100 -> #VALUE! | AE13: =AH12+AI12 -> 933084.45 | AF13: =SUMIFS(Sheet!G:G,Sheet!A:A, ">="&B13,Sheet!A:A, "<="&EOMONTH(B13,0)) -> 9404.8709 | AG13: =Charges!R20+Charges!Q20 -> 18428.061 | AH13: =AE13+AF13-AG13 -> 924061.26 | AI13: 0 | AJ13: =(AH13-AE13)/AE13*100 -> -0.96702829 | AK13: =AN12+AO12 -> 4468593.9 | AL13: =SUMIFS(Sheet!H:H,Sheet!A:A, ">="&B13,Sheet!A:A, "<="&EOMONTH(B13,0)) -> 45040.456 | AM13: =Charges!T20+Charges!S20 -> 88253.024 | AN13: =AK13+AL13-AM13 -> 4425381.4 | AO13: =11500000/3 -> 3833333.3 | AP13: =(AN13-AK13)/AK13*100 -> -0.96702829 | AQ13: ='Clients Balance'!I214 -> 833333 | AR13: =SUMIFS(Sheet!I:I,Sheet!A:A, ">="&B13,Sheet!A:A, "<="&EOMONTH(B13,0)) -> 8399.4426 | AS13: =Charges!U20+Charges!V20 -> 16458.009 | AT13: =AQ13+AR13-AS13 -> 825274.43 | AV13: =(AT13-AQ13)/AQ13*100 -> -0.96702829 | AW13: ='Clients Balance'!J214 -> 1666666 | AX13: =SUMIFS(Sheet!J:J,Sheet!A:A, ">="&B13,Sheet!A:A, "<="&EOMONTH(B13,0)) -> 16798.885 | AY13: =Charges!W20+Charges!X20 -> 32916.017 | AZ13: =AW13+AX13-AY13 -> 1650548.9 | BB13: =(AZ13-AW13)/AW13*100 -> -0.96702829 | BC13: ='Clients Balance'!K214 -> 833333 | BD13: =SUMIFS(Sheet!K:K,Sheet!A:A, ">="&B13,Sheet!A:A, "<="&EOMONTH(B13,0)) -> 8399.4426 | BE13: =Charges!Y20+Charges!Z20 -> 16458.009 | BF13: =BC13+BD13-BE13 -> 825274.43 | BH13: =(BF13-BC13)/BC13*100 -> -0.96702829 | BI13: 486297 | BJ13: =SUMIFS(Sheet!L:L,Sheet!A:A, ">="&B13,Sheet!A:A, "<="&EOMONTH(B13,0)) -> 4901.5505 | BK13: =Charges!AA20+Charges!AB20 -> 9604.18 | BL13: =BI13+BJ13-BK13 -> 481594.37 | BM13: 0 | BN13: =(BL13-BI13)/BI13*100 -> -0.96702829 | BO13: 486297 | BP13: =SUMIFS(Sheet!M:M,Sheet!A:A, ">="&B13,Sheet!A:A, "<="&EOMONTH(B13,0)) -> 4901.5505 | BQ13: =Charges!AC20+Charges!AD20 -> 9604.18 | BR13: =BO13+BP13-BQ13 -> 481594.37 | BT13: =(BR13-BO13)/BO13*100 -> -0.96702829 | BU13: 833333 | BV13: =SUMIFS(Sheet!N:N,Sheet!A:A, ">="&B13,Sheet!A:A, "<="&EOMONTH(B13,0)) -> 73733.354 | BW13: =Charges!AE20+Charges!AF20 -> 13250.669 | BX13: =BU13+BV13-BW13 -> 893815.68 | BY13: CLOSED | BZ13: =(BX13-BU13)/BU13*100 -> 7.2579251 | CA13: 500000 | CB13: =SUMIFS(Sheet!O:O,Sheet!A:A, ">="&B13,Sheet!A:A, "<="&EOMONTH(B13,0)) -> 7318.3564 | CC13: =Charges!AG20+Charges!AH20 -> 7260.8037 | CD13: =CA13+CB13-CC13 -> 500057.55 | CE13: 0 | CF13: =(CD13-CA13)/CA13*100 -> 0.011510543 | CY13: =F13+M13+S13+AE13+AK13+BC13+AW13+AQ13+BO13+BI13+BX13+CA13 -> 20132035 | CZ13: =CY13*3 -> 60396104 | DA13: =CZ13*0.7 -> 42277273
A14: 45804 | B14: =EDATE(B13,1) -> 45778 | C14: =sum('PROP DAILY PNL'!B227:B247) -> -824834 | D14: =Charges!H21 -> 496882 | E14: =C14-D14 -> -1321716 | F14: =I13-J13+K13 -> 6759900.8 | G14: =SUMIFS(Sheet!C:C,Sheet!A:A, ">="&B14,Sheet!A:A, "<="&EOMONTH(B14,0)) -> -227361.69 | H14: =Charges!I21+Charges!J21 -> 138353.18 | I14: =F14+G14-H14 -> 6394185.9 | J14: 150000 | K14: 29407 | L14: =(I14-F14)/F14*100 -> -5.4100626 | M14: =P13+Q13 -> 1460762.1 | N14: =SUMIFS(Sheet!D:D,Sheet!A:A, ">="&B14,Sheet!A:A, "<="&EOMONTH(B14,0)) -> -49131.098 | O14: =Charges!K21+Charges!L21 -> 29897.049 | P14: =M14+N14-O14 -> 1381734 | Q14: 0 | R14: =(P14-M14)/M14*100 -> -5.4100626 | S14: =V13+W13 -> 1207479 | T14: =SUMIFS(Sheet!E:E,Sheet!A:A, ">="&B14,Sheet!A:A, "<="&EOMONTH(B14,0)) -> -40612.202 | U14: =Charges!M21+Charges!N21 -> 24713.167 | V14: =S14+T14-U14 -> 1142153.6 | W14: 0 | X14: =(V14-S14)/S14*100 -> -5.4100626 | Z14: =SUMIFS(Sheet!F:F,Sheet!A:A, ">="&B14,Sheet!A:A, "<="&EOMONTH(B14,0)) -> 0 | AA14: =Charges!O21+Charges!P21 -> 0 | AB14: =Y14+Z14-AA14 -> 0 | AD14: =(AB14-Y14)/Y14*100 -> #DIV/0! | AE14: =AH13+AI13 -> 924061.26 | AF14: =SUMIFS(Sheet!G:G,Sheet!A:A, ">="&B14,Sheet!A:A, "<="&EOMONTH(B14,0)) -> -31079.765 | AG14: =Charges!R21+Charges!Q21 -> 18912.528 | AH14: =AE14+AF14-AG14 -> 874068.96 | AI14: 0 | AJ14: =(AH14-AE14)/AE14*100 -> -5.4100626 | AK14: =AN13+AO13 -> 8258714.7 | AL14: =SUMIFS(Sheet!H:H,Sheet!A:A, ">="&B14,Sheet!A:A, "<="&EOMONTH(B14,0)) -> -277460.48 | AM14: =Charges!T21+Charges!S21 -> 167218.69 | AN14: =AK14+AL14-AM14 -> 7814035.5 | AO14: 0 | AP14: =(AN14-AK14)/AK14*100 -> -5.3843629 | AQ14: =AT13+AU13 -> 825274.43 | AR14: =SUMIFS(Sheet!I:I,Sheet!A:A, ">="&B14,Sheet!A:A, "<="&EOMONTH(B14,0)) -> -27757.181 | AS14: =Charges!U21+Charges!V21 -> 16890.683 | AT14: =AQ14+AR14-AS14 -> 780626.57 | AU14: 0 | AV14: =(AT14-AQ14)/AQ14*100 -> -5.4100626 | AW14: =AZ13+BA13 -> 1650548.9 | AX14: =SUMIFS(Sheet!J:J,Sheet!A:A, ">="&B14,Sheet!A:A, "<="&EOMONTH(B14,0)) -> -55514.362 | AY14: =Charges!W21+Charges!X21 -> 33781.366 | AZ14: =AW14+AX14-AY14 -> 1561253.1 | BB14: =(AZ14-AW14)/AW14*100 -> -5.4100626 | BC14: =BF13+BG13 -> 825274.43 | BD14: =SUMIFS(Sheet!K:K,Sheet!A:A, ">="&B14,Sheet!A:A, "<="&EOMONTH(B14,0)) -> -27757.181 | BE14: =Charges!Y21+Charges!Z21 -> 16890.683 | BF14: =BC14+BD14-BE14 -> 780626.57 | BG14: 0 | BH14: =(BF14-BC14)/BC14*100 -> -5.4100626 | BI14: =BL13+BM13 -> 481594.37 | BJ14: =SUMIFS(Sheet!L:L,Sheet!A:A, ">="&B14,Sheet!A:A, "<="&EOMONTH(B14,0)) -> -16197.887 | BK14: =Charges!AA21+Charges!AB21 -> 9856.6701 | BL14: =BI14+BJ14-BK14 -> 455539.81 | BO14: =BR13+BS13 -> 481594.37 | BP14: =SUMIFS(Sheet!M:M,Sheet!A:A, ">="&B14,Sheet!A:A, "<="&EOMONTH(B14,0)) -> -16197.887 | BQ14: =Charges!AC21+Charges!AD21 -> 9856.6701 | BR14: =BO14+BP14-BQ14 -> 455539.81 | BU14: 0 | CA14: =CD13+CE13 -> 500057.55 | CB14: =SUMIFS(Sheet!O:O,Sheet!A:A, ">="&B14,Sheet!A:A, "<="&EOMONTH(B14,0)) -> -16818.875 | CC14: =Charges!AG21+Charges!AH21 -> 10234.551 | CD14: =CA14+CB14-CC14 -> 473004.13 | CE14: 0 | CF14: =(CD14-CA14)/CA14*100 -> -5.4100626 | CG14: 300000 | CH14: =SUMIFS(Sheet!P:P,Sheet!A:A, ">="&B14,Sheet!A:A, "<="&EOMONTH(B14,0)) -> -10033.983 | CI14: =Charges!AI21+Charges!AJ21 -> 5814.1667 | CJ14: =CG14+CH14-CI14 -> 284151.85 | CK14: 0 | CL14: =(CJ14-CG14)/CG14*100 -> -5.2827167 | CM14: 833333 | CN14: =SUMIFS(Sheet!Q:Q,Sheet!A:A, ">="&B14,Sheet!A:A, "<="&EOMONTH(B14,0)) -> -28911.41 | CO14: =Charges!AK21+Charges!AL21 -> 14465.796 | CP14: =CM14+CN14-CO14 -> 789955.79 | CQ14: 0 | CR14: =(CP14-CM14)/CM14*100 -> -5.2052668 | CY14: =F14+M14+S14+Y14+AE14+AK14+BC14+AW14+AQ14+CA14+BI14+BO14+CM14 -> 24208595 | CZ14: =CY14*3 -> 72625785 | DA14: =CZ14*0.83 -> 60279401
A15: 45836 | B15: =EDATE(B14,1) -> 45809 | F15: =I14-J14+K14 -> 6273592.9 | G15: =SUMIFS(Sheet!C:C,Sheet!A:A, ">="&B15,Sheet!A:A, "<="&EOMONTH(B15,0)) -> 84639.974 | H15: =Charges!I22+Charges!J22 -> 130076.42 | I15: =F15+G15-H15 -> 6228156.5 | J15: 150000 | K15: 37641 | L15: =(I15-F15)/F15*100 -> -0.72424918 | M15: =P14+Q14 -> 1381734 | N15: =SUMIFS(Sheet!D:D,Sheet!A:A, ">="&B15,Sheet!A:A, "<="&EOMONTH(B15,0)) -> 18641.619 | O15: =Charges!K22+Charges!L22 -> 28648.831 | P15: =M15+N15-O15 -> 1371726.8 | R15: =(P15-M15)/M15*100 -> -0.72425022 | S15: =V14+W14 -> 1142153.6 | T15: =SUMIFS(Sheet!E:E,Sheet!A:A, ">="&B15,Sheet!A:A, "<="&EOMONTH(B15,0)) -> 15409.328 | U15: =Charges!M22+Charges!N22 -> 23681.307 | V15: =S15+T15-U15 -> 1133881.6 | X15: =(V15-S15)/S15*100 -> -0.72424401 | Z15: =SUMIFS(Sheet!F:F,Sheet!A:A, ">="&B15,Sheet!A:A, "<="&EOMONTH(B15,0)) -> 0 | AA15: =Charges!O22+Charges!P22 -> 0 | AB15: =Y15+Z15-AA15 -> 0 | AD15: =(AB15-Y15)/Y15*100 -> #DIV/0! | AE15: =AH14+AI14 -> 874068.96 | AF15: =SUMIFS(Sheet!G:G,Sheet!A:A, ">="&B15,Sheet!A:A, "<="&EOMONTH(B15,0)) -> 11792.473 | AG15: =Charges!R22+Charges!Q22 -> 22216.153 | AH15: =AE15+AF15-AG15 -> 863645.28 | AJ15: =(AH15-AE15)/AE15*100 -> -1.1925466 | AK15: =AN14+AO14 -> 7814035.5 | AL15: =SUMIFS(Sheet!H:H,Sheet!A:A, ">="&B15,Sheet!A:A, "<="&EOMONTH(B15,0)) -> 105422.81 | AM15: =Charges!T22+Charges!S22 -> 160210.49 | AN15: =AK15+AL15-AM15 -> 7759247.8 | AP15: =(AN15-AK15)/AK15*100 -> -0.7011446 | AQ15: =AT14+AU14 -> 780626.57 | AR15: =SUMIFS(Sheet!I:I,Sheet!A:A, ">="&B15,Sheet!A:A, "<="&EOMONTH(B15,0)) -> 10531.798 | AS15: =Charges!U22+Charges!V22 -> 20910.183 | AT15: =AQ15+AR15-AS15 -> 770248.19 | AV15: =(AT15-AQ15)/AQ15*100 -> -1.3294942 | AW15: =AZ14+BA14 -> 1561253.1 | AX15: =SUMIFS(Sheet!J:J,Sheet!A:A, ">="&B15,Sheet!A:A, "<="&EOMONTH(B15,0)) -> 21063.596 | AY15: =Charges!W22+Charges!X22 -> 41820.366 | AZ15: =AW15+AX15-AY15 -> 1540496.4 | BB15: =(AZ15-AW15)/AW15*100 -> -1.3294942 | BC15: =BF14+BG14 -> 780626.57 | BD15: =SUMIFS(Sheet!K:K,Sheet!A:A, ">="&B15,Sheet!A:A, "<="&EOMONTH(B15,0)) -> 10531.798 | BE15: =Charges!Y22+Charges!Z22 -> 20910.183 | BF15: =BC15+BD15-BE15 -> 770248.19 | BH15: =(BF15-BC15)/BC15*100 -> -1.3294942 | BI15: =BL14+BM14 -> 455539.81 | BJ15: =SUMIFS(Sheet!L:L,Sheet!A:A, ">="&B15,Sheet!A:A, "<="&EOMONTH(B15,0)) -> 6145.9005 | BK15: =Charges!AA22+Charges!AB22 -> 11366.816 | BL15: =BI15+BJ15-BK15 -> 450318.9 | BO15: =BR14+BS14 -> 455539.81 | BP15: =SUMIFS(Sheet!M:M,Sheet!A:A, ">="&B15,Sheet!A:A, "<="&EOMONTH(B15,0)) -> 6145.9005 | BQ15: =Charges!AC22+Charges!AD22 -> 11366.816 | BR15: =BO15+BP15-BQ15 -> 450318.9 | CA15: =CD14+CE14 -> 473004.13 | CB15: =SUMIFS(Sheet!O:O,Sheet!A:A, ">="&B15,Sheet!A:A, "<="&EOMONTH(B15,0)) -> 6381.5197 | CC15: =Charges!AG22+Charges!AH22 -> 9807.2103 | CD15: =CA15+CB15-CC15 -> 469578.44 | CG15: =CJ14+CK14 -> 284151.85 | CH15: =SUMIFS(Sheet!P:P,Sheet!A:A, ">="&B15,Sheet!A:A, "<="&EOMONTH(B15,0)) -> 3833.6254 | CI15: =Charges!AI22+Charges!AJ22 -> 5891.6031 | CJ15: =CG15+CH15-CI15 -> 282093.87 | CK15: 0 | CL15: =(CJ15-CG15)/CG15*100 -> -0.72425278 | CM15: =CP14+CQ14 -> 789955.79 | CN15: =SUMIFS(Sheet!Q:Q,Sheet!A:A, ">="&B15,Sheet!A:A, "<="&EOMONTH(B15,0)) -> 10657.663 | CO15: =Charges!AK22+Charges!AL22 -> 21040.57 | CP15: =CM15+CN15-CO15 -> 779572.89 | CY15: =F15+M15+S15+AE15+AK15+BC15+AW15+AQ15+CA15+BI15+BO15+CM15+CG15 -> 23066283 | CZ15: =CY15*3 -> 69198848 | DA15: =CZ15*0.83 -> 57435044
